[65.371990204] 2019-02-02 19:14:36,458 - INFO - launcher: Starting sanity checks
[66.398143768] 2019-02-02 19:14:36,459 - INFO - launcher: Checking for Python 3.5+
[66.849231720] 2019-02-02 19:14:36,459 - INFO - launcher: Checking console encoding
[67.267894745] 2019-02-02 19:14:36,460 - INFO - launcher: Ensuring we're in the right environment
[1249.104022980] 2019-02-02 19:14:37,641 - INFO - launcher: Required checks passed.
[1249.619960785] 2019-02-02 19:14:37,642 - INFO - launcher: Optional checks passed.

######################### PRE-RUN SANITY CHECKS PASSED #########################

[1.9822359085083008] 2019-02-02 19:14:38,375 - WARNING - musicbot.config | In config.py::MainThread(4321387392), line 116 in run_checks: i18n file does not exist. Trying to fallback to config/i18n/en.json.
[1.9826381206512451] 2019-02-02 19:14:38,375 - INFO - musicbot.config | In config.py::MainThread(4321387392), line 127 in run_checks: Using i18n: config/i18n/en.json
[1.9832260608673096] 2019-02-02 19:14:38,376 - WARNING - musicbot.config | In config.py::MainThread(4321387392), line 211 in create_empty_file_ifnoexist: Creating config/blacklist.txt
[1.9836950302124023] 2019-02-02 19:14:38,376 - WARNING - musicbot.config | In config.py::MainThread(4321387392), line 211 in create_empty_file_ifnoexist: Creating config/whitelist.txt
[1.9869210720062256] 2019-02-02 19:14:38,379 - DEBUG - musicbot.config | In config.py::MainThread(4321387392), line 296 in find_autoplaylist: Copying _autoplaylist.txt to autoplaylist.txt
[1.9873690605163574] 2019-02-02 19:14:38,380 - DEBUG - musicbot.bot | In bot.py::MainThread(4321387392), line 226 in _setup_logging: Set logging level to INFO
[1.9880521297454834] 2019-02-02 19:14:38,380 - INFO - musicbot.permissions | In permissions.py::MainThread(4321387392), line 62 in __init__: Permissions file not found, copying example_permissions.ini
[1.9921560287475586] 2019-02-02 19:14:38,385 - DEBUG - musicbot.json | In json.py::MainThread(4321387392), line 8 in __init__: Init JSON obj with config/i18n/en.json
[1.9942421913146973] 2019-02-02 19:14:38,387 - WARNING - musicbot.aliases | In aliases.py::MainThread(4321387392), line 22 in __init__: Aliases file not found, copying example_aliases.json
[2.0599482059478760] 2019-02-02 19:14:38,452 - INFO - musicbot.bot | In bot.py::MainThread(4321387392), line 91 in __init__: Starting MusicBot 1.9.8_4
[2.0606009960174561] 2019-02-02 19:14:38,453 - INFO - musicbot.bot | In bot.py::MainThread(4321387392), line 97 in __init__: Loaded autoplaylist with 2531 entries
[2.4475369453430176] 2019-02-02 19:14:38,840 - DEBUG - musicbot.spotify | In spotify.py::MainThread(4321387392), line 74 in get_token: Created a new access token: {'access_token': 'BQDlZu0nd3ekEeO2Kufobpvg5Rv7E7U8mjki_oqzqrH60sgoipKGqBeDWVyYVUmOwK41E8tIX8HezAITqvk', 'token_type': 'Bearer', 'expires_in': 3600, 'scope': '', 'expires_at': 1549167278}
[2.4478549957275391] 2019-02-02 19:14:38,840 - INFO - musicbot.bot | In bot.py::MainThread(4321387392), line 122 in __init__: Authenticated with Spotify successfully using client ID and secret.
[5.1332800388336182] 2019-02-02 19:14:41,526 - DEBUG - musicbot.bot | In bot.py::MainThread(4321387392), line 922 in on_ready: Connection established, ready to go.
[5.1335060596466064] 2019-02-02 19:14:41,526 - DEBUG - musicbot.bot | In bot.py::MainThread(4321387392), line 340 in _cache_app_info: Caching app info
[5.2459981441497803] 2019-02-02 19:14:41,638 - DEBUG - musicbot.bot | In bot.py::MainThread(4321387392), line 744 in _scheck_ensure_env: Ensuring data folders exist
[5.2468941211700439] 2019-02-02 19:14:41,639 - DEBUG - musicbot.bot | In bot.py::MainThread(4321387392), line 760 in _scheck_server_permissions: Checking server permissions
[5.2470350265502930] 2019-02-02 19:14:41,639 - DEBUG - musicbot.bot | In bot.py::MainThread(4321387392), line 764 in _scheck_autoplaylist: Auditing autoplaylist
[5.2471370697021484] 2019-02-02 19:14:41,639 - DEBUG - musicbot.bot | In bot.py::MainThread(4321387392), line 768 in _scheck_configs: Validating config
[5.2472701072692871] 2019-02-02 19:14:41,640 - DEBUG - musicbot.config | In config.py::MainThread(4321387392), line 217 in async_validate: Validating options...
[5.2481532096862793] 2019-02-02 19:14:41,641 - DEBUG - musicbot.config | In config.py::MainThread(4321387392), line 231 in async_validate: Acquired owner id via API
[5.2483730316162109] 2019-02-02 19:14:41,641 - DEBUG - musicbot.bot | In bot.py::MainThread(4321387392), line 771 in _scheck_configs: Validating permissions config
[5.2485499382019043] 2019-02-02 19:14:41,641 - DEBUG - musicbot.permissions | In permissions.py::MainThread(4321387392), line 94 in async_validate: Validating permissions...
[5.2489240169525146] 2019-02-02 19:14:41,641 - DEBUG - musicbot.permissions | In permissions.py::MainThread(4321387392), line 98 in async_validate: Fixing automatic owner group
[5.2491579055786133] 2019-02-02 19:14:41,642 - INFO - musicbot.bot | In bot.py::MainThread(4321387392), line 939 in on_ready: Connected: 541420984662491152/EpicMusic#3706
[5.2495031356811523] 2019-02-02 19:14:41,642 - INFO - musicbot.bot | In bot.py::MainThread(4321387392), line 947 in on_ready: Owner:     489227480062754827/GEVids#3918

[5.2497849464416504] 2019-02-02 19:14:41,642 - INFO - musicbot.bot | In bot.py::MainThread(4321387392), line 950 in on_ready: Guild List:
[5.2500162124633789] 2019-02-02 19:14:41,642 - INFO - musicbot.bot | In bot.py::MainThread(4321387392), line 954 in on_ready:  - GEVids Discord in the works
[5.2503070831298828] 2019-02-02 19:14:41,643 - INFO - musicbot.bot | In bot.py::MainThread(4321387392), line 1010 in on_ready: Not bound to any text channels
[5.2506041526794434] 2019-02-02 19:14:41,643 - INFO - musicbot.bot | In bot.py::MainThread(4321387392), line 1036 in on_ready: Not autojoining any voice channels
[33.2548198699951172] 2019-02-02 19:15:09,647 - INFO - musicbot.bot | In bot.py::MainThread(4321387392), line 2644 in on_message: 489227480062754827/GEVids#3918: e!help
[43.0119571685791016] 2019-02-02 19:15:19,404 - ERROR - musicbot.bot | In bot.py::MainThread(4321387392), line 910 in on_error: Exception in on_voice_state_update
Traceback (most recent call last):
  File "/Library/Frameworks/Python.framework/Versions/3.6/lib/python3.6/site-packages/discord/client.py", line 227, in _run_event
    await coro(*args, **kwargs)
  File "/Users/amypark/Desktop/MusicBotUSE/musicbot/bot.py", line 2842, in on_voice_state_update
    player = await self.get_player(channel)
  File "/Users/amypark/Desktop/MusicBotUSE/musicbot/bot.py", line 431, in get_player
    'Use %ssummon to summon it to your voice channel.' % self.config.command_prefix)
musicbot.exceptions.CommandError: The bot is not in a voice channel.  Use e!summon to summon it to your voice channel.
[45.8955121040344238] 2019-02-02 19:15:22,288 - INFO - musicbot.bot | In bot.py::MainThread(4321387392), line 2644 in on_message: 489227480062754827/GEVids#3918: e!summon
[46.7599902153015137] 2019-02-02 19:15:23,152 - INFO - musicbot.bot | In bot.py::MainThread(4321387392), line 1893 in cmd_summon: Joining GEVids Discord in the works/Music
[46.7636220455169678] 2019-02-02 19:15:23,156 - DEBUG - musicbot.bot | In bot.py::MainThread(4321387392), line 511 in on_player_stop: Running on_player_stop
[71.2004821300506592] 2019-02-02 19:15:47,593 - INFO - musicbot.bot | In bot.py::MainThread(4321387392), line 2644 in on_message: 489227480062754827/GEVids#3918: e!play oh yeah yeah
[72.6719551086425781] 2019-02-02 19:15:49,064 - DEBUG - musicbot.bot | In bot.py::MainThread(4321387392), line 1380 in cmd_play: {'_type': 'url', 'url': 'ytsearch:oh yeah yeah', 'ie_key': None, 'extractor': 'generic', 'webpage_url': 'oh yeah yeah', 'webpage_url_basename': 'oh yeah yeah', 'extractor_key': 'Generic'}
[77.1263120174407959] 2019-02-02 19:15:53,519 - DEBUG - musicbot.entry | In entry.py::MainThread(4321387392), line 56 in get_ready_future: Created future for None
[77.1282260417938232] 2019-02-02 19:15:53,521 - DEBUG - musicbot.bot | In bot.py::MainThread(4321387392), line 595 in on_player_entry_added: Running on_player_entry_added
[77.1283988952636719] 2019-02-02 19:15:53,521 - DEBUG - musicbot.bot | In bot.py::MainThread(4321387392), line 680 in serialize_queue: Serializing queue for 496319611466153984
[77.1304399967193604] 2019-02-02 19:15:53,523 - INFO - musicbot.entry | In entry.py::MainThread(4321387392), line 292 in _really_download: Download started: https://www.youtube.com/watch?v=7fFSupGfZME
[79.1280798912048340] 2019-02-02 19:15:55,520 - DEBUG - musicbot.entry | In entry.py::MainThread(4321387392), line 56 in get_ready_future: Created future for None
[79.2220380306243896] 2019-02-02 19:15:55,614 - INFO - musicbot.entry | In entry.py::MainThread(4321387392), line 302 in _really_download: Download complete: https://www.youtube.com/watch?v=7fFSupGfZME
[79.2246439456939697] 2019-02-02 19:15:55,617 - FFMPEG - musicbot.player | In player.py::MainThread(4321387392), line 273 in _play: Creating player with options: -nostdin -vn audio_cache/youtube-7fFSupGfZME-MaximilianMus_-_Oh_Yeah_Yeah.webm
[79.2380759716033936] 2019-02-02 19:15:55,630 - DEBUG - musicbot.player | In player.py::MainThread(4321387392), line 284 in _play: Playing <discord.player.PCMVolumeTransformer object at 0x111439f28> using <discord.voice_client.VoiceClient object at 0x11141ba58>
[79.2409901618957520] 2019-02-02 19:15:55,633 - DEBUG - musicbot.bot | In bot.py::MainThread(4321387392), line 458 in on_player_play: Running on_player_play
[79.2436439990997314] 2019-02-02 19:15:55,636 - DEBUG - musicbot.bot | In bot.py::MainThread(4321387392), line 680 in serialize_queue: Serializing queue for 496319611466153984
[90.2161250114440918] 2019-02-02 19:16:06,608 - INFO - musicbot.bot | In bot.py::MainThread(4321387392), line 2864 in on_voice_state_update: Pausing in GEVids Discord in the works/Music (empty channel)
[90.2168571949005127] 2019-02-02 19:16:06,609 - DEBUG - musicbot.bot | In bot.py::MainThread(4321387392), line 506 in on_player_pause: Running on_player_pause
[91.2051391601562500] 2019-02-02 19:16:07,597 - INFO - musicbot.bot | In bot.py::MainThread(4321387392), line 2853 in on_voice_state_update: Unpausing in GEVids Discord in the works/Music
[91.2058250904083252] 2019-02-02 19:16:07,598 - DEBUG - musicbot.bot | In bot.py::MainThread(4321387392), line 502 in on_player_resume: Running on_player_resume
[103.3018140792846680] 2019-02-02 19:16:19,694 - INFO - musicbot.bot | In bot.py::MainThread(4321387392), line 2644 in on_message: 489227480062754827/GEVids#3918: e!help
[106.5957450866699219] 2019-02-02 19:16:22,988 - INFO - musicbot.bot | In bot.py::MainThread(4321387392), line 2644 in on_message: 489227480062754827/GEVids#3918: e!clear
[117.8664588928222656] 2019-02-02 19:16:34,259 - INFO - musicbot.bot | In bot.py::MainThread(4321387392), line 2644 in on_message: 489227480062754827/GEVids#3918: e!remove
[117.8685152530670166] 2019-02-02 19:16:34,261 - ERROR - musicbot.bot | In bot.py::MainThread(4321387392), line 2773 in on_message: Error in remove: CommandError: There's nothing to remove!
Traceback (most recent call last):
  File "/Users/amypark/Desktop/MusicBotUSE/musicbot/bot.py", line 2751, in on_message
    response = await handler(**handler_kwargs)
  File "/Users/amypark/Desktop/MusicBotUSE/musicbot/bot.py", line 1971, in cmd_remove
    raise exceptions.CommandError(self.str.get('cmd-remove-none', "There's nothing to remove!"), expire_in=20)
musicbot.exceptions.CommandError: There's nothing to remove!
[121.2182018756866455] 2019-02-02 19:16:37,611 - INFO - musicbot.bot | In bot.py::MainThread(4321387392), line 2644 in on_message: 489227480062754827/GEVids#3918: e!disconnect
[121.5232110023498535] 2019-02-02 19:16:37,916 - ERROR - musicbot.bot | In bot.py::MainThread(4321387392), line 910 in on_error: Exception in on_voice_state_update
Traceback (most recent call last):
  File "/Library/Frameworks/Python.framework/Versions/3.6/lib/python3.6/site-packages/discord/client.py", line 227, in _run_event
    await coro(*args, **kwargs)
  File "/Users/amypark/Desktop/MusicBotUSE/musicbot/bot.py", line 2842, in on_voice_state_update
    player = await self.get_player(channel)
  File "/Users/amypark/Desktop/MusicBotUSE/musicbot/bot.py", line 431, in get_player
    'Use %ssummon to summon it to your voice channel.' % self.config.command_prefix)
musicbot.exceptions.CommandError: The bot is not in a voice channel.  Use e!summon to summon it to your voice channel.
[123.1358039379119873] 2019-02-02 19:16:39,528 - ERROR - musicbot.bot | In bot.py::MainThread(4321387392), line 910 in on_error: Exception in on_voice_state_update
Traceback (most recent call last):
  File "/Library/Frameworks/Python.framework/Versions/3.6/lib/python3.6/site-packages/discord/client.py", line 227, in _run_event
    await coro(*args, **kwargs)
  File "/Users/amypark/Desktop/MusicBotUSE/musicbot/bot.py", line 2842, in on_voice_state_update
    player = await self.get_player(channel)
  File "/Users/amypark/Desktop/MusicBotUSE/musicbot/bot.py", line 431, in get_player
    'Use %ssummon to summon it to your voice channel.' % self.config.command_prefix)
musicbot.exceptions.CommandError: The bot is not in a voice channel.  Use e!summon to summon it to your voice channel.
